test/unit/match_several/state.json
[
	{
		"bids": [
			{
				"price": 1023000000,
				"size": 5234591011,
				"order_id": 0,
				"sender_id": "24095cf6defa4985aab0d9f6393a14fb"
			}
		],
		"asks": [],
		"state_num": 2,
		"output_seq": 2
	},
	{
		"bids": [
			{
				"price": 1024000000,
				"size": 1023400000,
				"order_id": 1,
				"sender_id": "693a498fe9454542908f2814154a95d4"
			},
			{
				"price": 1023000000,
				"size": 5234591011,
				"order_id": 0,
				"sender_id": "24095cf6defa4985aab0d9f6393a14fb"
			}
		],
		"asks": [],
		"state_num": 2,
		"output_seq": 4
	},
	{
		"bids": [
			{
				"price": 1024000000,
				"size": 1023400000,
				"order_id": 1,
				"sender_id": "693a498fe9454542908f2814154a95d4"
			},
			{
				"price": 1023000000,
				"size": 5234591011,
				"order_id": 0,
				"sender_id": "24095cf6defa4985aab0d9f6393a14fb"
			},
			{
				"price": 1023000000,
				"size": 1020000000,
				"order_id": 2,
				"sender_id": "0f9ab1d843a44f9a95f55950d15ab3ba"
			}
		],
		"asks": [],
		"state_num": 2,
		"output_seq": 6
	},
	{
		"bids": [
			{
				"price": 1024000000,
				"size": 1023400000,
				"order_id": 1,
				"sender_id": "693a498fe9454542908f2814154a95d4"
			},
			{
				"price": 1023000000,
				"size": 5234591011,
				"order_id": 0,
				"sender_id": "24095cf6defa4985aab0d9f6393a14fb"
			},
			{
				"price": 1023000000,
				"size": 1020000000,
				"order_id": 2,
				"sender_id": "0f9ab1d843a44f9a95f55950d15ab3ba"
			}
		],
		"asks": [
			{
				"price": 1800000000,
				"size": 8056912305,
				"order_id": 5,
				"sender_id": "a23e0db0f7d74aa79d1f9f8ffdf689b0"
			}
		],
		"state_num": 2,
		"output_seq": 8
	},
	{
		"bids": [
			{
				"price": 1024000000,
				"size": 1023400000,
				"order_id": 1,
				"sender_id": "693a498fe9454542908f2814154a95d4"
			},
			{
				"price": 1023000000,
				"size": 5234591011,
				"order_id": 0,
				"sender_id": "24095cf6defa4985aab0d9f6393a14fb"
			},
			{
				"price": 1023000000,
				"size": 1020000000,
				"order_id": 2,
				"sender_id": "0f9ab1d843a44f9a95f55950d15ab3ba"
			}
		],
		"asks": [
			{
				"price": 1100000000,
				"size": 120000000,
				"order_id": 3,
				"sender_id": "bfdc2003f2594cfda220a0b0d2bcfecb"
			},
			{
				"price": 1800000000,
				"size": 8056912305,
				"order_id": 5,
				"sender_id": "a23e0db0f7d74aa79d1f9f8ffdf689b0"
			}
		],
		"state_num": 2,
		"output_seq": 10
	},
	{
		"bids": [
			{
				"price": 1024000000,
				"size": 1023400000,
				"order_id": 1,
				"sender_id": "693a498fe9454542908f2814154a95d4"
			},
			{
				"price": 1023000000,
				"size": 5234591011,
				"order_id": 0,
				"sender_id": "24095cf6defa4985aab0d9f6393a14fb"
			},
			{
				"price": 1023000000,
				"size": 1020000000,
				"order_id": 2,
				"sender_id": "0f9ab1d843a44f9a95f55950d15ab3ba"
			}
		],
		"asks": [
			{
				"price": 1100000000,
				"size": 120000000,
				"order_id": 3,
				"sender_id": "bfdc2003f2594cfda220a0b0d2bcfecb"
			},
			{
				"price": 1100000000,
				"size": 210000000,
				"order_id": 4,
				"sender_id": "2c99757c274648c3b8242da738d9de7f"
			},
			{
				"price": 1800000000,
				"size": 8056912305,
				"order_id": 5,
				"sender_id": "a23e0db0f7d74aa79d1f9f8ffdf689b0"
			}
		],
		"state_num": 2,
		"output_seq": 12
	},
	{
		"bids": [
			{
				"price": 1024000000,
				"size": 1023400000,
				"order_id": 1,
				"sender_id": "693a498fe9454542908f2814154a95d4"
			},
			{
				"price": 1023000000,
				"size": 5234591011,
				"order_id": 0,
				"sender_id": "24095cf6defa4985aab0d9f6393a14fb"
			},
			{
				"price": 1023000000,
				"size": 1020000000,
				"order_id": 2,
				"sender_id": "0f9ab1d843a44f9a95f55950d15ab3ba"
			}
		],
		"asks": [
			{
				"price": 1100000000,
				"size": 110000000,
				"order_id": 4,
				"sender_id": "2c99757c274648c3b8242da738d9de7f"
			},
			{
				"price": 1800000000,
				"size": 8056912305,
				"order_id": 5,
				"sender_id": "a23e0db0f7d74aa79d1f9f8ffdf689b0"
			}
		],
		"state_num": 2,
		"output_seq": 16
	},
	{
		"bids": [
			{
				"price": 1023000000,
				"size": 4237991011,
				"order_id": 0,
				"sender_id": "24095cf6defa4985aab0d9f6393a14fb"
			},
			{
				"price": 1023000000,
				"size": 1020000000,
				"order_id": 2,
				"sender_id": "0f9ab1d843a44f9a95f55950d15ab3ba"
			}
		],
		"asks": [
			{
				"price": 1100000000,
				"size": 110000000,
				"order_id": 4,
				"sender_id": "2c99757c274648c3b8242da738d9de7f"
			},
			{
				"price": 1800000000,
				"size": 8056912305,
				"order_id": 5,
				"sender_id": "a23e0db0f7d74aa79d1f9f8ffdf689b0"
			}
		],
		"state_num": 2,
		"output_seq": 20
	}
]
